<?xml version="1.0"?>
<!-- Basic WAM-V with gazebo plugins for dynamics -->
<robot xmlns:xacro="http://ros.org/wiki/xacro"
       name="WAM-V">
  <xacro:arg name="locked" default="false" />
  <xacro:arg name="thruster_config" default="H" />
  <xacro:arg name="front_camera_enabled" default="true" />
  <xacro:arg name="chase_camera_enabled" default="false" />
  <xacro:arg name="arucos_enabled" default="true" />
  <xacro:arg name="gps_enabled" default="true" />
  <xacro:arg name="imu_enabled" default="false" />
  <xacro:arg name="lidar_enabled" default="false" />
  <xacro:arg name="ground_truth_enabled" default="false" />
  <xacro:arg name="vrx_sensors_enabled" default="false" />
  <xacro:arg name="pinger_enabled" default="false" />
  <xacro:arg name="ball_shooter_enabled" default="false" />
  <xacro:arg name="thruster_namespace" default="thrusters/"/>
  <xacro:arg name="camera_namespace" default="cameras/"/>  
  <xacro:arg name="sensor_namespace" default="sensors/"/>
  <xacro:arg name="pinger_namespace" default="pingers/"/>
  <xacro:arg name="shooter_namespace" default="shooters/"/>
  
  <!-- Note: this is only used for some sensors that do not correctly use the 
  robotNamespace parameter -->
  <xacro:arg name="namespace" default="wamv"/>
  <xacro:property name="save_video_enabled" value="false" scope="local"/>    
  <xacro:property name="thruster_namespace" value="$(arg thruster_namespace)" scope="global" />
  <xacro:property name="camera_namespace" value="$(arg camera_namespace)" scope="global" />
  <xacro:property name="sensor_namespace" value="$(arg sensor_namespace)" scope="global" />
  <xacro:property name="pinger_namespace" value="$(arg pinger_namespace)" scope="global" />
  <xacro:property name="shooter_namespace" value="$(arg shooter_namespace)" scope="global" />
  <xacro:property name="namespace" value="$(arg namespace)" scope="global" />      
  <!-- <xacro:property name="platform_namespace" default="platform" scope="local"/>  -->
  
  <!-- Sensor yaml file -->
  <xacro:arg name="yaml_component_generation" default="false"/>
  <xacro:arg name="component_xacro_file" default = ""/>

  <!-- Thruster yaml file -->
  <xacro:arg name="yaml_thruster_generation" default="false"/>
  <xacro:arg name="thruster_xacro_file" default = ""/>

  <!-- === The WAM-V platform === -->
  <xacro:include filename="$(find wamv_gazebo)/urdf/wamv_gazebo.xacro"/>
   
  <!-- === Batteries ===-->
  <xacro:include filename="$(find wamv_description)/urdf/battery.xacro"/>
  <xacro:battery prefix="left" position="0 1 0.45" orientation="0 0 0" />
  <xacro:battery prefix="right" position="0 -1 0.45" orientation="0 0 0"/>
  
  
  <!-- === QR Codes ===-->
  <xacro:if value="$(arg arucos_enabled)">
    <xacro:include filename="$(find wamv_description)/urdf/qrcodes.xacro"/>
    <xacro:Aruco72 prefix="small" position=".4 0 1.31" orientation="0 0 0" scale="0.5 0.5 0.5"/>
    <xacro:Aruco129 prefix="large" position="-.4 0 1.31" orientation="0 0 0" scale="1 1 1"/>
    <!--<xacro:aruco_platform position="0 0 1.3" orientation="0 0 0"/>-->
  </xacro:if>
  
  <!-- === Thrusters === -->
  <!-- Use thruster yaml file if given -->
  <xacro:if value="$(arg yaml_thruster_generation)">
    <xacro:wamv_gazebo thruster_layout="$(arg thruster_xacro_file)"/>
  </xacro:if>
  
  <!-- Otherwise, add thrusters based on thruster_config variable -->
  <xacro:unless value="$(arg yaml_thruster_generation)">
    <xacro:property name="thruster_conf" value="$(arg thruster_config)"/>

    <!-- Default WAM-V with two aft thrusters -->
    <xacro:if value="${thruster_conf == 'H'}">
       <xacro:wamv_gazebo thruster_layout="$(find wamv_gazebo)/urdf/thruster_layouts/wamv_aft_thrusters.xacro"/>
    </xacro:if>

    <!-- WAMV with "T" thruster configuration -->
    <xacro:if value="${thruster_conf == 'T'}">
      <xacro:wamv_gazebo thruster_layout="$(find wamv_gazebo)/urdf/thruster_layouts/wamv_t_thrusters.xacro"/>
    </xacro:if>

    <!-- WAMV with "X" thruster configuration -->
    <xacro:if value="${thruster_conf == 'X'}">
      <xacro:wamv_gazebo thruster_layout="$(find wamv_gazebo)/urdf/thruster_layouts/wamv_x_thrusters.xacro"/>
    </xacro:if>
  </xacro:unless>

  <!-- === Decide if we lock the robot to the world === -->
  <xacro:if value="$(arg locked)">
    <gazebo>
      <link name="wamv_external_link"/>
      <joint name="wamv_external_pivot_joint" type="universal">
        <parent>wamv::wamv/base_link</parent>
        <child>wamv_external_link</child>
        <axis>
          <xyz>1 0 0</xyz>
        </axis>
        <axis2>
          <xyz>0 1 0</xyz>
        </axis2>
      </joint>
      <joint name="wamv_external_riser" type="prismatic">
        <parent>world</parent>
        <child>wamv_external_link</child>
        <axis>
          <limit>
            <lower>-3</lower>
            <upper>3</upper>
          </limit>
          <xyz>0 0 1</xyz>
        </axis>
      </joint>
    </gazebo>
  </xacro:if>

  <!-- === Sensors === -->
  <!-- Use sensor yaml file if given -->
  <xacro:if value="$(arg yaml_component_generation)">
    <xacro:include filename="$(arg component_xacro_file)"/>
    <xacro:yaml_components />

    <!-- Add CPU Cases -->
    <xacro:include filename="$(find wamv_description)/urdf/cpu_cases.xacro" />
    <xacro:cpu_cases position="-0.15 0 1.53" orientation="0 0 0"/>
  </xacro:if>
  
  <!-- Otherwise, add sensors based on enable variables -->
  <xacro:unless value="$(arg yaml_component_generation)">
    <!-- Add a front camera -->
    <xacro:if value="$(arg front_camera_enabled)">
      <xacro:wamv_front_camera name="front_camera" y="0.0" x="2.5" Y="${radians(180)}" P="${radians(-15)}" scale="0.01 0.01 0.01" vid_save="${save_video_enabled}"/>
    </xacro:if>
    
    <xacro:if value="$(arg chase_camera_enabled)">
      <xacro:wamv_chase_camera name="chase_camera" z="5" y="0.3" x="-15"  P="${radians(0)}" vid_save="${save_video_enabled}"/>
    </xacro:if>
    
    <!-- Add simulated GPS -->
    <xacro:if value="$(arg gps_enabled)">
      <xacro:wamv_gps name="gps_wamv" x="-0.95" y="1" z="0.45"/>
    </xacro:if>
    
    <!-- Add Simulated IMU -->
    <xacro:if value="$(arg imu_enabled)">
      <xacro:wamv_imu name="imu_wamv" y="-0.2" />
    </xacro:if>
    
    <!-- Add 3D LIDAR -->
    <xacro:if value="$(arg lidar_enabled)">
      <xacro:lidar name="lidar_wamv" y="-0.3" type="16_beam"/>
    </xacro:if>
    
    <!-- Add P3D ground truth -->
    <xacro:if value="$(arg ground_truth_enabled)">
      <xacro:wamv_p3d name="p3d_wamv"/>
    </xacro:if>

    <!-- Add pinger -->
    <xacro:if value="$(arg pinger_enabled)">
      <xacro:wamv_pinger name="pinger" position="1.0 0 -1.0" />
    </xacro:if>

    <!-- Add ball shooter (default pitch angle: ~-60 deg)
    <xacro:if value="$(arg ball_shooter_enabled)">
      <xacro:wamv_ball_shooter name="ball_shooter" x="0.54" y="0.30" z="1.296" pitch="-1.04"/>
    </xacro:if>
     -->
    <!-- ==== VRX sensor configuration ==== -->
    <xacro:if value="$(arg vrx_sensors_enabled)">
    
      <!-- Add CPU Cases -->
      <xacro:include filename="$(find wamv_description)/urdf/cpu_cases.xacro" />
      <xacro:cpu_cases position="-0.15 0 1.53" orientation="0 0 0"/>
    
      <!-- Add a stereo camera pair -->
      <xacro:wamv_camera name="front_left_camera" y="0.1" x="0.75" P="${radians(15)}" />
      <xacro:wamv_camera name="front_right_camera" y="-0.1" x="0.75" P="${radians(15)}" />
    
      <!-- Add a camera facing right -->
      <xacro:wamv_camera name="middle_right_camera" y="-0.45" P="${radians(15)}" Y="${radians(-90)}" post_Y="${radians(-90)}" />
    
      <!-- Add simulated GPS -->
      <xacro:wamv_gps name="gps_wamv" x="-0.85" />
    
      <!-- Add Simulated IMU -->
      <xacro:wamv_imu name="imu_wamv" y="-0.2" />
    
      <!-- Add 3D LIDAR -->
      <xacro:lidar name="lidar_wamv" type="16_beam"/>

      <!-- Add pinger -->
      <xacro:wamv_pinger name="pinger" position="1.0 0 -1.0" />
      
      <!-- Add ball shooter (default pitch angle: ~-60 deg) -->
      <xacro:wamv_ball_shooter name="ball_shooter" x="0.54" y="0.30" z="1.296" pitch="-1.04"/>

    </xacro:if>
  </xacro:unless>
 
     <!-- Trying to set up 
    <gazebo>
      <link name="${namespace}/drone_static">
      </link>
      -->
      <!--
      <joint name="platform_init_joint" type="universal">
        <parent>wamv::wamv/drone_platform_link</parent>
        <child>drone_static</child>
        <axis>
          <xyz>1 0 0</xyz>
        </axis>
        <axis2>
          <xyz>0 1 0</xyz>
        </axis2>
      </joint>
      -->
      <!--
      <joint name="drone_platform_static_joint" type="prismatic">
      <pose>0 0 0 0 0 0</pose>
        <parent>world</parent>
        <child>wamv/drone_static</child>
        <axis>
          <limit>
            <lower>-3</lower>
            <upper>3</upper>
          </limit>
          <xyz>0 0 1</xyz>
        </axis>
      </joint>
      
      <link name="${platform_namespace}/static_link">
  </link>
      
      
      <joint name="world_drone_platform_joint" type="fixed">
        <parent>world</parent>
        <child>drone_platform_static</child>
      </joint>
      </gazebo>
     
    <xacro:include filename="$(find wamv_description)/urdf/drone_platform.xacro"/>
  <xacro:drone_platform position="0 0 1.33"/>
     -->
<!--<origin xyz="0 0 1.33" rpy="0 0 0"/>
       <parent link="world"/> <link name="world"/>
      <parent link="${namespace}/drone_platform_link"/>   -->
</robot>
